============ upmed-web Coverage and Unit Report Generated on 1605805796 ============ \n\n
.........
----------------------------------------------------------------------
Ran 9 tests in 2.204s

OK
/usr/lib/python3.6/runpy.py:125: RuntimeWarning: 'upmed-api.tst.api.hcp_test.hcp_test' found in sys.modules after import of package 'upmed-api.tst.api.hcp_test', but prior to execution of 'upmed-api.tst.api.hcp_test.hcp_test'; this may result in unpredictable behaviour
  warn(RuntimeWarning(msg))
E..........
======================================================================
ERROR: test_editProfile (__main__.HCPTestCase)
----------------------------------------------------------------------
Traceback (most recent call last):
  File "/mnt/c/Users/willp/Documents/4156/UpMed/upmed-api/tst/api/hcp_test/hcp_test.py", line 328, in test_editProfile
    hcp = response.json()
  File "/mnt/c/Users/willp/Documents/4156/UpMed/env/lib/python3.6/site-packages/requests/models.py", line 900, in json
    return complexjson.loads(self.text, **kwargs)
  File "/usr/lib/python3.6/json/__init__.py", line 354, in loads
    return _default_decoder.decode(s)
  File "/usr/lib/python3.6/json/decoder.py", line 339, in decode
    obj, end = self.raw_decode(s, idx=_w(s, 0).end())
  File "/usr/lib/python3.6/json/decoder.py", line 357, in raw_decode
    raise JSONDecodeError("Expecting value", s, err.value) from None
json.decoder.JSONDecodeError: Expecting value: line 1 column 1 (char 0)

----------------------------------------------------------------------
Ran 11 tests in 2.867s

FAILED (errors=1)
/usr/lib/python3.6/runpy.py:125: RuntimeWarning: 'upmed-api.tst.api.appointment_test.appointment_test' found in sys.modules after import of package 'upmed-api.tst.api.appointment_test', but prior to execution of 'upmed-api.tst.api.appointment_test.appointment_test'; this may result in unpredictable behaviour
  warn(RuntimeWarning(msg))
....
----------------------------------------------------------------------
Ran 4 tests in 3.758s

OK
